Workbook

Sheet Introduction
A1: Hurricane Impact Database — ERD Overview
A2: A four-entity relational design for hurricane events, weather observations, locations, and recorded impacts.
A4: Relationship Map
A6: Source Entity | B6: Relationship | C6: Target Entity | D6: Cardinality | E6: Foreign Key | F6: Required
A7: Hurricane | B7: has observations | C7: Meteorological Data | D7: 1 to 0..* | E7: meteorological_data.hurricane_id | F7: Yes
A8: Location | B8: measured at | C8: Meteorological Data | D8: 1 to 0..* | E8: meteorological_data.location_id | F8: Yes
A9: Meteorological Data | B9: records destruction | C9: Destruction | D9: 1 to 0..* | E9: destruction_entity.MD_ID | F9: Yes
A12: Entity | B12: Worksheet | C12: Primary Key | D12: Attributes | E12: Role | F12: Data entry
A13: Hurricane | B13: hurricane_entity | C13: hurricane_ID | D13: 5 | E13: Parent event | F13: One row per hurricane
A14: Meteorological Data | B14: meteorological_data | C14: MD_ID | D14: 9 | E14: Observation bridge | F14: One row per location/time observation
A15: Destruction | B15: destruction_entity | C15: destruction_ID | D15: 7 | E15: Impact outcome | F15: One row per impact record
A16: Location | B16: location_entity | C16: location_id | D16: 6 | E16: Spatial reference | F16: One row per unique location
A20: How to use
A21: Enter records below the attribute headers on each entity sheet. Populate parent records first, then use their IDs in the related foreign-key columns.

Sheet hurricane_entity
A1: Hurricane Entity
A2: Stores each hurricane event and its active time window.
A3: Primary key: hurricane_ID • Parent of meteorological_data through hurricane_id
A5: hurricane_ID | B5: name | C5: start_datetime | D5: end_datetime | E5: source
A6: 0 | B6: Melissa | C6: 45951.25 | D6: 45962.5 | E6: NHC Tropical Cyclone Report: Hurricane Melissa (AL132025), 19 May 2026 revised version, https://www.nhc.noaa.gov/data/tcr/AL132025_Melissa.pdf — start: formation of Tropical Storm Melissa 0600 UTC 21 Oct 2025 (PDF p.3; Table 1, p.21). End: 'dissipated' 1200 UTC 1 Nov 2025 (Table 1, PDF p.22; text p.5). Becomes extratropical 1200 UTC 31 Oct (p.5).
A7: 1 | B7: Ian | C7: 2022-09-23 6:00 UTC | D7: 2022-10-01 12:00 UTC | E7: NHC Tropical Cyclone Report: Hurricane Ian (AL092022), 12 March 2026 revised version (original 2 April 2023), https://www.nhc.noaa.gov/data/tcr/AL092022_Ian.pdf — start: genesis as a tropical depression 0600 UTC 23 Sep 2022 (PDF p.3; Table 1, p.20). End: 'dissipation' 1200 UTC 1 Oct 2022 (Table 1, p.21; text p.4). Becomes extratropical 0000 UTC 1 Oct (p.4).
A8: 2 | B8: Fiona | C8: 2022-09-14 06:00 UTC | D8: 2022-09-28 00:00 UTC | E8: NHC Tropical Cyclone Report: Hurricane Fiona (AL072022), 23 March 2023 https://www.nhc.noaa.gov/data/tcr/AL072022_Fiona.pdf — genesis as a tropical depression at 0600 UTC 14 Sep (Table 1, PDF p.14); became extratropical 0000 UTC 24 Sep; dissipated 0000 UTC 28 Sep (Table 1, PDF pp.15–16).

Sheet meteorological_data
A1: Meteorological Data Entity
A2: Stores weather observations for a hurricane at a specific location and time window.
A3: Primary key: MD_ID • Foreign keys: hurricane_id → Hurricane, location_id → Location
A5: MD_ID | B5: hurricane_id | C5: location_id | D5: start_datetime | E5: end_datetime | F5: avg_wind_speed | G5: total_rainfall | H5: avg_temperature | I5: source
A6: 0 | B6: 0 | C6: 0 | D6: 45958.5 | E6: 45958.875 | F6: =AVERAGEIFS(best_track_ref!$E$6:$E$54,best_track_ref!$A$6:$A$54,">="&(D6-1/86400),best_track_ref!$A$6:$A$54,"<="&(E6+1/86400)) -> 156.66667 | G6: 817.1 | I6: NHC Tropical Cyclone Report: Hurricane Melissa (AL132025), 19 May 2026 revised version, https://www.nhc.noaa.gov/data/tcr/AL132025_Melissa.pdf — Window: peak intensity 1200 UTC 28 Oct (p.4, p.6) to emergence off Jamaica's north coast ~2100 UTC 28 Oct (p.4). avg_wind_speed (kt, 1-min sustained) = average of best-track winds in window, from best_track_ref (Table 1, PDF p.21–22). total_rainfall (mm) = highest storm total, Knock Patrick, Manchester Parish, 32.17 in / 817.1 mm (p.10). avg_temperature: not reported.
A7: 1 | B7: 0 | C7: 1 | D7: 45959.306 | E7: 45959.542 | F7: =AVERAGEIFS(best_track_ref!$E$6:$E$54,best_track_ref!$A$6:$A$54,">="&(D7-1/86400),best_track_ref!$A$6:$A$54,"<="&(E7+1/86400)) -> 92.5 | G7: 670 | I7: NHC Tropical Cyclone Report: Hurricane Melissa (AL132025), 19 May 2026 revised version, https://www.nhc.noaa.gov/data/tcr/AL132025_Melissa.pdf — Window: landfall 0720 UTC 29 Oct to emergence off north coast ~1300 UTC 29 Oct (p.4). avg_wind_speed (kt) = average of best-track winds in window (Table 1, PDF p.22). total_rainfall (mm) = highest storm total, Vega Murcia, 26.38 in / 670 mm (p.10). avg_temperature: not reported.
A8: 2 | B8: 0 | C8: 2 | D8: 45959.927 | E8: 45960.083 | F8: =AVERAGEIFS(best_track_ref!$E$6:$E$54,best_track_ref!$A$6:$A$54,">="&(D8-1/86400),best_track_ref!$A$6:$A$54,"<="&(E8+1/86400)) -> 80 | G8: 198 | I8: NHC Tropical Cyclone Report: Hurricane Melissa (AL132025), 19 May 2026 revised version, https://www.nhc.noaa.gov/data/tcr/AL132025_Melissa.pdf — Window: landfall Long Island 2215 UTC 29 Oct to landfall San Salvador 0200 UTC 30 Oct (p.4, p.8). avg_wind_speed (kt) = average of best-track winds in window (Table 1, PDF p.22). total_rainfall (mm) = highest reported, Cockburn Town, 7.78 in / 198 mm (p.11). avg_temperature: not reported.
A9: 3 | B9: 0 | C9: 3 | G9: 934 | I9: NHC Tropical Cyclone Report: Hurricane Melissa (AL132025), 19 May 2026 revised version, https://www.nhc.noaa.gov/data/tcr/AL132025_Melissa.pdf — total_rainfall (mm) = highest storm total, Camp Perrin (Sud Dept), 36.77 in / 934 mm (p.10). Observation window and wind speed not given for Haiti (no landfall) so left blank. avg_temperature: not reported.
A10: 4 | B10: 0 | C10: 4 | D10: 45958.667 | E10: 45958.667 | F10: 47 | I10: NHC Tropical Cyclone Report: Hurricane Melissa (AL132025), 19 May 2026 revised version, https://www.nhc.noaa.gov/data/tcr/AL132025_Melissa.pdf — Table 3, PDF p.27 (station, coordinates, sustained 47 kt, gust 114 kt at 1600 UTC 28 Oct, min pressure 913.5 mb). Site of the highest gust reported in Jamaica (text p.6–7). Jamaica station sustained wind = 1-hour average (Table 3 footnote b, PDF p.32). No rainfall reported. Window = time of reported maximum sustained wind. avg_wind_speed (kt) = reported sustained wind at the station, not a best-track average. avg_temperature: not reported.
A11: 5 | B11: 0 | C11: 5 | D11: 45958.833 | E11: 45958.833 | F11: 57 | I11: NHC Tropical Cyclone Report: Hurricane Melissa (AL132025), 19 May 2026 revised version, https://www.nhc.noaa.gov/data/tcr/AL132025_Melissa.pdf — Table 3, PDF p.27 (sustained 57 kt, gust 105 kt, min pressure 958 mb). Jamaica station sustained wind = 1-hour average (Table 3 footnote b, PDF p.32). No rainfall reported. Window = time of reported maximum sustained wind. avg_wind_speed (kt) = reported sustained wind at the station, not a best-track average. avg_temperature: not reported.
A12: 6 | B12: 0 | C12: 6 | D12: 45958.958 | E12: 45958.958 | F12: 45 | I12: NHC Tropical Cyclone Report: Hurricane Melissa (AL132025), 19 May 2026 revised version, https://www.nhc.noaa.gov/data/tcr/AL132025_Melissa.pdf — Table 3, PDF p.26 (sustained 45 kt, gust 90 kt, min pressure 972.5 mb). Jamaica station sustained wind = 1-hour average (Table 3 footnote b, PDF p.32). Table rainfall (4.43 in) is flagged with an unexplained asterisk, so left blank. Window = time of reported maximum sustained wind. avg_wind_speed (kt) = reported sustained wind at the station, not a best-track average. avg_temperature: not reported.
A13: 7 | B13: 0 | C13: 7 | D13: 45958.75 | E13: 45958.75 | F13: 40 | I13: NHC Tropical Cyclone Report: Hurricane Melissa (AL132025), 19 May 2026 revised version, https://www.nhc.noaa.gov/data/tcr/AL132025_Melissa.pdf — Table 3, PDF p.26 (sustained 40 kt, gust 96 kt, min pressure 964.6 mb). Jamaica station sustained wind = 1-hour average (Table 3 footnote b, PDF p.32). No rainfall reported. Window = time of reported maximum sustained wind. avg_wind_speed (kt) = reported sustained wind at the station, not a best-track average. avg_temperature: not reported.
A14: 8 | B14: 0 | C14: 8 | D14: 45958.708 | E14: 45958.708 | F14: 56 | G14: =ROUND(20.01*25.4,1) -> 508.3 | I14: NHC Tropical Cyclone Report: Hurricane Melissa (AL132025), 19 May 2026 revised version, https://www.nhc.noaa.gov/data/tcr/AL132025_Melissa.pdf — Table 3, PDF p.27 (sustained 56 kt, gust 90 kt, min pressure 974.8 mb, rain 20.01 in). Jamaica station sustained wind = 1-hour average (Table 3 footnote b, PDF p.32). Rainfall converted from inches (x25.4). Window = time of reported maximum sustained wind. avg_wind_speed (kt) = reported sustained wind at the station, not a best-track average. avg_temperature: not reported.
A15: 9 | B15: 0 | C15: 9 | D15: 45958.625 | E15: 45958.625 | F15: 54 | I15: NHC Tropical Cyclone Report: Hurricane Melissa (AL132025), 19 May 2026 revised version, https://www.nhc.noaa.gov/data/tcr/AL132025_Melissa.pdf — Table 3, PDF p.27 (sustained 54 kt, gust 93 kt, min pressure 972.5 mb). Jamaica station sustained wind = 1-hour average (Table 3 footnote b, PDF p.32). No rainfall reported. Window = time of reported maximum sustained wind. avg_wind_speed (kt) = reported sustained wind at the station, not a best-track average. avg_temperature: not reported.
A16: 10 | B16: 0 | C16: 10 | D16: 45958.833 | E16: 45958.833 | F16: 44 | G16: =ROUND(9.29*25.4,1) -> 236 | I16: NHC Tropical Cyclone Report: Hurricane Melissa (AL132025), 19 May 2026 revised version, https://www.nhc.noaa.gov/data/tcr/AL132025_Melissa.pdf — Table 3, PDF p.27 (sustained 44 kt, gust 88 kt, min pressure 960.2 mb, rain 9.29 in). Jamaica station sustained wind = 1-hour average (Table 3 footnote b, PDF p.32). Rainfall converted from inches (x25.4). Window = time of reported maximum sustained wind. avg_wind_speed (kt) = reported sustained wind at the station, not a best-track average. avg_temperature: not reported.
A17: 11 | B17: 0 | C17: 11 | D17: 45958.917 | E17: 45958.917 | F17: 44 | G17: =ROUND(10.66*25.4,1) -> 270.8 | I17: NHC Tropical Cyclone Report: Hurricane Melissa (AL132025), 19 May 2026 revised version, https://www.nhc.noaa.gov/data/tcr/AL132025_Melissa.pdf — Table 3, PDF p.26 (sustained 44 kt, gust 85 kt, min pressure 965.9 mb, rain 10.66 in). Jamaica station sustained wind = 1-hour average (Table 3 footnote b, PDF p.32). Rainfall converted from inches (x25.4). Window = time of reported maximum sustained wind. avg_wind_speed (kt) = reported sustained wind at the station, not a best-track average. avg_temperature: not reported.
A18: 12 | B18: 0 | C18: 12 | D18: 45958.833 | E18: 45958.833 | F18: 25 | G18: =ROUND(13.16*25.4,1) -> 334.3 | I18: NHC Tropical Cyclone Report: Hurricane Melissa (AL132025), 19 May 2026 revised version, https://www.nhc.noaa.gov/data/tcr/AL132025_Melissa.pdf — Table 3, PDF p.24 (sustained 25 kt, gust 68 kt, min pressure 984.1 mb, rain 13.16 in). Jamaica station sustained wind = 1-hour average (Table 3 footnote b, PDF p.32). Rainfall converted from inches (x25.4). Window = time of reported maximum sustained wind. avg_wind_speed (kt) = reported sustained wind at the station, not a best-track average. avg_temperature: not reported.
A19: 13 | B19: 0 | C19: 13 | D19: 45958.75 | E19: 45958.75 | F19: 37 | G19: =ROUND(7.35*25.4,1) -> 186.7 | I19: NHC Tropical Cyclone Report: Hurricane Melissa (AL132025), 19 May 2026 revised version, https://www.nhc.noaa.gov/data/tcr/AL132025_Melissa.pdf — Table 3, PDF p.25 (sustained 37 kt, gust 69 kt, min pressure 993.7 mb, rain 7.35 in). Strongest gust in the Kingston area (text p.7). Jamaica station sustained wind = 1-hour average (Table 3 footnote b, PDF p.32). Rainfall converted from inches (x25.4). Window = time of reported maximum sustained wind. avg_wind_speed (kt) = reported sustained wind at the station, not a best-track average. avg_temperature: not reported.
A20: 14 | B20: 0 | C20: 14 | D20: 45958.583 | E20: 45958.583 | F20: 10 | G20: =ROUND(22.32*25.4,1) -> 566.9 | I20: NHC Tropical Cyclone Report: Hurricane Melissa (AL132025), 19 May 2026 revised version, https://www.nhc.noaa.gov/data/tcr/AL132025_Melissa.pdf — Table 3, PDF p.25 (sustained 10 kt, gust 37 kt, min pressure 993.6 mb, rain 22.32 in). Jamaica station sustained wind = 1-hour average (Table 3 footnote b, PDF p.32). Rainfall converted from inches (x25.4). Window = time of reported maximum sustained wind. avg_wind_speed (kt) = reported sustained wind at the station, not a best-track average. avg_temperature: not reported.
A21: 15 | B21: 0 | C21: 15 | D21: 45958.333 | E21: 45958.333 | F21: 40 | I21: NHC Tropical Cyclone Report: Hurricane Melissa (AL132025), 19 May 2026 revised version, https://www.nhc.noaa.gov/data/tcr/AL132025_Melissa.pdf — Table 3, PDF p.24 (ICAO site; sustained 40 kt, gust 56 kt, min pressure 998.0 mb; no data after 1000 UTC 28 Oct). ICAO sustained wind = 2-min average (footnote b, p.32). No rainfall reported. Window = time of reported maximum sustained wind. avg_wind_speed (kt) = reported sustained wind at the station, not a best-track average. avg_temperature: not reported.
A22: 16 | B22: 0 | C22: 16 | D22: 45958.792 | E22: 45958.792 | F22: 41 | I22: NHC Tropical Cyclone Report: Hurricane Melissa (AL132025), 19 May 2026 revised version, https://www.nhc.noaa.gov/data/tcr/AL132025_Melissa.pdf — Table 3, PDF p.24 (ICAO site; sustained 41 kt, gust 50 kt, min pressure 995.9 mb). ICAO sustained wind = 2-min average (footnote b, p.32). No rainfall reported. Window = time of reported maximum sustained wind. avg_wind_speed (kt) = reported sustained wind at the station, not a best-track average. avg_temperature: not reported.
A23: 17 | B23: 0 | C23: 17 | D23: 45959.104 | E23: 45959.104 | F23: 59 | G23: =ROUND(14.71*25.4,1) -> 373.6 | I23: NHC Tropical Cyclone Report: Hurricane Melissa (AL132025), 19 May 2026 revised version, https://www.nhc.noaa.gov/data/tcr/AL132025_Melissa.pdf — Table 3, PDF p.28 (INSMET station; sustained 59 kt (10-min), gust 101 kt, min pressure 967.7 mb, rain 14.71 in); eye passed over 0845–0856 UTC 29 Oct (text p.8). Report gives no coordinates. Rainfall converted from inches (x25.4). Window = time of reported maximum sustained wind. avg_wind_speed (kt) = reported sustained wind at the station, not a best-track average. avg_temperature: not reported.
A24: 18 | B24: 0 | C24: 18 | D24: 45959.076 | E24: 45959.076 | F24: 70 | G24: =ROUND(13.2*25.4,1) -> 335.3 | I24: NHC Tropical Cyclone Report: Hurricane Melissa (AL132025), 19 May 2026 revised version, https://www.nhc.noaa.gov/data/tcr/AL132025_Melissa.pdf — Table 3, PDF p.28 (INSMET elevated station; sustained 70 kt (10-min), gust 118 kt, rain 13.20 in); highest sustained wind and gust in Cuba (text p.8). Report gives no coordinates. Rainfall converted from inches (x25.4). Window = time of reported maximum sustained wind. avg_wind_speed (kt) = reported sustained wind at the station, not a best-track average. avg_temperature: not reported.
A25: 19 | B25: 0 | C25: 19 | D25: 45959.327 | E25: 45959.327 | F25: 51 | G25: =ROUND(6.5*25.4,1) -> 165.1 | I25: NHC Tropical Cyclone Report: Hurricane Melissa (AL132025), 19 May 2026 revised version, https://www.nhc.noaa.gov/data/tcr/AL132025_Melissa.pdf — Table 3, PDF p.28 (ICAO site; sustained 51 kt, gust 65 kt, min pressure 996.5 mb, rain 6.50 in; data gap 0751–2151 UTC 29 Oct). Coordinates printed in the table duplicate those of the Santiago airport, so left blank. Rainfall converted from inches (x25.4). Window = time of reported maximum sustained wind. avg_wind_speed (kt) = reported sustained wind at the station, not a best-track average. avg_temperature: not reported.
A26: 20 | B26: 0 | C26: 20 | D26: 45959.49 | E26: 45959.49 | F26: 62 | G26: =ROUND(10.84*25.4,1) -> 275.3 | I26: NHC Tropical Cyclone Report: Hurricane Melissa (AL132025), 19 May 2026 revised version, https://www.nhc.noaa.gov/data/tcr/AL132025_Melissa.pdf — Table 3, PDF p.29 (INSMET station; sustained 62 kt (10-min), gust 68 kt, min pressure 983.4 mb, rain 10.84 in). Report gives no coordinates. Rainfall converted from inches (x25.4). Window = time of reported maximum sustained wind. avg_wind_speed (kt) = reported sustained wind at the station, not a best-track average. avg_temperature: not reported.
A27: 21 | B27: 0 | C27: 21 | D27: 45959.083 | E27: 45959.083 | F27: 47 | G27: =ROUND(4.04*25.4,1) -> 102.6 | I27: NHC Tropical Cyclone Report: Hurricane Melissa (AL132025), 19 May 2026 revised version, https://www.nhc.noaa.gov/data/tcr/AL132025_Melissa.pdf — Table 3, PDF p.29 (INSMET station; sustained 47 kt (10-min), gust 68 kt, min pressure 999.0 mb, rain 4.04 in). Report gives no coordinates. Rainfall converted from inches (x25.4). Window = time of reported maximum sustained wind. avg_wind_speed (kt) = reported sustained wind at the station, not a best-track average. avg_temperature: not reported.
A28: 22 | B28: 0 | C28: 22 | D28: 45959.853 | E28: 45959.853 | F28: 66 | I28: NHC Tropical Cyclone Report: Hurricane Melissa (AL132025), 19 May 2026 revised version, https://www.nhc.noaa.gov/data/tcr/AL132025_Melissa.pdf — Table 3, PDF p.32 (sustained 66 kt, gust 77 kt, min pressure 980.7 mb); strongest winds recorded in the Bahamas (text p.8). No rainfall reported. Window = time of reported maximum sustained wind. avg_wind_speed (kt) = reported sustained wind at the station, not a best-track average. avg_temperature: not reported.
A29: 23 | B29: 0 | C29: 23 | D29: 45960.006 | E29: 45960.006 | F29: 45 | I29: NHC Tropical Cyclone Report: Hurricane Melissa (AL132025), 19 May 2026 revised version, https://www.nhc.noaa.gov/data/tcr/AL132025_Melissa.pdf — Table 3, PDF p.32 (sustained 45 kt, gust 61 kt, min pressure 968.8 mb). No rainfall reported. Window = time of reported maximum sustained wind. avg_wind_speed (kt) = reported sustained wind at the station, not a best-track average. avg_temperature: not reported.
A30: 24 | B30: 0 | C30: 24 | D30: 45959.871 | E30: 45959.871 | F30: 35 | I30: NHC Tropical Cyclone Report: Hurricane Melissa (AL132025), 19 May 2026 revised version, https://www.nhc.noaa.gov/data/tcr/AL132025_Melissa.pdf — Table 3, PDF p.32 (sustained 35 kt, gust 44 kt, min pressure 966.5 mb; Weather Underground site with ~6 mb low bias, text p.8). No rainfall reported. Window = time of reported maximum sustained wind. avg_wind_speed (kt) = reported sustained wind at the station, not a best-track average. avg_temperature: not reported.
A31: 25 | B31: 0 | C31: 25 | G31: 198 | I31: NHC Tropical Cyclone Report: Hurricane Melissa (AL132025), 19 May 2026 revised version, https://www.nhc.noaa.gov/data/tcr/AL132025_Melissa.pdf — Table 3, PDF p.32 and text p.11: highest Bahamas rainfall 7.78 in / 198 mm. No wind reported at this site. Observation window not specified in the report. avg_temperature: not reported.
A32: 26 | B32: 0 | C32: 26 | D32: 45961.163 | E32: 45961.163 | F32: 43 | I32: NHC Tropical Cyclone Report: Hurricane Melissa (AL132025), 19 May 2026 revised version, https://www.nhc.noaa.gov/data/tcr/AL132025_Melissa.pdf — Table 3, PDF p.29 (ICAO site; sustained 43 kt, gust 60 kt, min pressure 996.9 mb). Impacts minor, no casualties (text p.15). No rainfall reported. Window = time of reported maximum sustained wind. avg_wind_speed (kt) = reported sustained wind at the station, not a best-track average. avg_temperature: not reported.
A33: 27 | B33: 0 | C33: 27 | D33: 45961.156 | E33: 45961.156 | F33: 68 | I33: NHC Tropical Cyclone Report: Hurricane Melissa (AL132025), 19 May 2026 revised version, https://www.nhc.noaa.gov/data/tcr/AL132025_Melissa.pdf — Table 3, PDF p.29 (sustained 68 kt at 46 m elevation, gust 86 kt, min pressure 991.9 mb). No rainfall reported. Window = time of reported maximum sustained wind. avg_wind_speed (kt) = reported sustained wind at the station, not a best-track average. avg_temperature: not reported.
A34: 28 | B34: 0 | C34: 28 | G34: 893 | I34: NHC Tropical Cyclone Report: Hurricane Melissa (AL132025), 19 May 2026 revised version, https://www.nhc.noaa.gov/data/tcr/AL132025_Melissa.pdf — Text p.10 (35.16 in / 893 mm, second-highest total in Haiti); Table 3, PDF p.30. Report gives no coordinates or wind data. Observation window not specified in the report. avg_temperature: not reported.
A35: 29 | B35: 0 | C35: 29 | G35: 856.5 | I35: NHC Tropical Cyclone Report: Hurricane Melissa (AL132025), 19 May 2026 revised version, https://www.nhc.noaa.gov/data/tcr/AL132025_Melissa.pdf — Text p.10 (33.72 in / 856.5 mm); Table 3, PDF p.30. Report gives no coordinates or wind data. Observation window not specified in the report. avg_temperature: not reported.
A36: 30 | B36: 0 | C36: 30 | G36: 835.6 | I36: NHC Tropical Cyclone Report: Hurricane Melissa (AL132025), 19 May 2026 revised version, https://www.nhc.noaa.gov/data/tcr/AL132025_Melissa.pdf — Text p.10 (32.90 in / 835.6 mm); Table 3, PDF p.30. Report gives no coordinates or wind data. Observation window not specified in the report. avg_temperature: not reported.
A37: 31 | B37: 0 | C37: 31 | G37: 737.2 | I37: NHC Tropical Cyclone Report: Hurricane Melissa (AL132025), 19 May 2026 revised version, https://www.nhc.noaa.gov/data/tcr/AL132025_Melissa.pdf — Text p.11 (29.02 in / 737.2 mm); Table 3, PDF p.31. Report gives no coordinates or wind data. Observation window not specified in the report. avg_temperature: not reported.
A38: 32 | B38: 0 | C38: 32 | G38: 507.4 | I38: NHC Tropical Cyclone Report: Hurricane Melissa (AL132025), 19 May 2026 revised version, https://www.nhc.noaa.gov/data/tcr/AL132025_Melissa.pdf — Text p.11 (19.98 in / 507.4 mm); Table 3, PDF p.31. Report gives no coordinates or wind data. Observation window not specified in the report. avg_temperature: not reported.
A39: 33 | B39: 0 | C39: 33 | G39: 453.1 | I39: NHC Tropical Cyclone Report: Hurricane Melissa (AL132025), 19 May 2026 revised version, https://www.nhc.noaa.gov/data/tcr/AL132025_Melissa.pdf — Text p.11 (17.84 in / 453.1 mm); Table 3, PDF p.31. Report gives no coordinates or wind data. Observation window not specified in the report. avg_temperature: not reported.
A40: 34 | B40: 0 | C40: 34 | I40: NHC Tropical Cyclone Report: Hurricane Melissa (AL132025), 19 May 2026 revised version, https://www.nhc.noaa.gov/data/tcr/AL132025_Melissa.pdf — Casualty table PDF p.12 and text p.15: moisture associated with Melissa caused heavy rain and flooding that contributed to three fatalities. No stations, coordinates, wind or rainfall reported. Observation window not specified in the report. avg_temperature: not reported.
A41: 35 | B41: 1 | C41: 35 | D41: 44831.354 | E41: 44831.583 | F41: =AVERAGE(best_track_ref_Ian!E23:E24) -> 105 | G41: 338 | I41: NHC Tropical Cyclone Report: Hurricane Ian (AL092022), 12 March 2026 revised version (original 2 April 2023), https://www.nhc.noaa.gov/data/tcr/AL092022_Ian.pdf — Window: landfall 0830 UTC 27 Sep to emergence over the SE Gulf of Mexico ~1400 UTC 27 Sep (p.3). avg_wind_speed (kt, 1-min sustained) = average of best-track winds in window, from best_track_ref_ian (Table 1, p.20). total_rainfall (mm) = highest total from INSMET stations in western Cuba (range 151.7–338 mm, p.12; station not named). Media reports of >500 mm not used (not instrument-based). avg_temperature: not reported.
...

Sheet destruction_entity
A1: Destruction Entity
A2: Stores human and financial impacts associated with a meteorological observation.
A3: Primary key: destruction_ID • Foreign key: MD_ID → Meteorological Data
A5: destruction_ID | B5: MD_ID | C5: deaths_direct | D5: deaths_indirect | E5: infrastructure_damage_usd | F5: economic_damage_overall_usd | G5: source
A6: 0 | B6: 0 | E6: 2900000000 | F6: 12200000000 | G6: NHC Tropical Cyclone Report: Hurricane Melissa (AL132025), 19 May 2026 revised version, https://www.nhc.noaa.gov/data/tcr/AL132025_Melissa.pdf — Deaths: 45 fatalities in Jamaica (PDF p.12 table; p.13); direct vs indirect split not available (p.13), so left blank. economic_damage_overall_usd = US$12.2 billion (NHC p.13; the NHC text labels it 'physical damage' / '41 percent of GDP', but IDB states US$12.2 billion is TOTAL damage and losses = ~56.7% of 2024 GDP per the Planning Institute of Jamaica, March 2026: https://www.iadb.org/en/blog/economic-analysis/jamaica-after-hurricane-melissa-building-resilience-through-disaster-risk-financing ). ADDITIONAL SOURCE (not in NHC report): infrastructure_damage_usd = US$2.9 billion (2,916.4 million in table) direct physical damage to infrastructure (power, telecoms, water, seaports, airports, roads, bridges) — World Bank / GFDRR, Global Rapid Post-Disaster Damage Estimation (GRADE): Hurricane Melissa 2025 Jamaica, Table ES.1, PDF p.12 (printed p.2), https://www.gfdrr.org/sites/default/files/publication/GRADE%20Jamaica_FIN.pdf (landing page https://www.gfdrr.org/en/JamaicaGRADE); also presented by the World Bank on 19 Nov 2025 (Jamaica Information Service: https://jis.gov.jm/st-elizabeth-st-james-westmoreland-sustained-us5-5-billion-in-damage-from-hurricane-melissa/ ). Preliminary Nov 2025 estimate of US$8.8 billion total physical damage, an earlier vintage than the US$12.2 billion.
A7: 1 | B7: 1 | C7: 0 | D7: 0 | G7: NHC Tropical Cyclone Report: Hurricane Melissa (AL132025), 19 May 2026 revised version, https://www.nhc.noaa.gov/data/tcr/AL132025_Melissa.pdf — Cuba: government assessment reported no fatalities attributed to Melissa (PDF p.14), recorded as 0 direct / 0 indirect. No USD damage estimate given (only counts, e.g. 900,000+ homes damaged/destroyed, p.14).
A8: 2 | B8: 3 | G8: NHC Tropical Cyclone Report: Hurricane Melissa (AL132025), 19 May 2026 revised version, https://www.nhc.noaa.gov/data/tcr/AL132025_Melissa.pdf — Haiti: at least 43 deaths, 25 in Petit-Goave (PDF p.12 table; p.13); cause breakdown not known so direct/indirect left blank. No USD damage estimate given.
A9: 3 | B9: 34 | G9: NHC Tropical Cyclone Report: Hurricane Melissa (AL132025), 19 May 2026 revised version, https://www.nhc.noaa.gov/data/tcr/AL132025_Melissa.pdf — Panama: heavy rain and flooding contributed to three fatalities (PDF p.15; total in casualty table p.12). Direct/indirect split not reported, so left blank. No USD damage given.
A10: 4 | B10: 26 | C10: 0 | D10: 0 | G10: NHC Tropical Cyclone Report: Hurricane Melissa (AL132025), 19 May 2026 revised version, https://www.nhc.noaa.gov/data/tcr/AL132025_Melissa.pdf — Bermuda: impacts minor; 'no reported casualties' (PDF p.15), recorded as 0 direct / 0 indirect. No USD damage given.
A11: 5 | B11: 31 | C11: 0 | D11: 0 | G11: NHC Tropical Cyclone Report: Hurricane Melissa (AL132025), 19 May 2026 revised version, https://www.nhc.noaa.gov/data/tcr/AL132025_Melissa.pdf — Dominican Republic: government assessment reported no fatalities attributed to Melissa (PDF p.14), recorded as 0. Damage reported as counts only (823 homes flooded, 21 partially affected, 2 destroyed, 29 aqueducts out of service affecting ~250,000 users; p.14), no USD figure.
A12: 6 | B12: 35 | C12: 3 | D12: 2 | G12: NHC Tropical Cyclone Report: Hurricane Ian (AL092022), 12 March 2026 revised version (original 2 April 2023), https://www.nhc.noaa.gov/data/tcr/AL092022_Ian.pdf — Cuba: 5 deaths, 3 direct (two wind, one unknown) and 2 indirect (clean-up accidents) (PDF p.13). More than 100,000 homes damaged or destroyed, ~60% of homes in Pinar del Río Province; entire island lost power (p.14). 'No monetary damage estimate available for Cuba' (p.14), so USD left blank.
A13: 7 | B13: 37 | C13: 66 | D13: 84 | F13: 109500000000 | G13: NHC Tropical Cyclone Report: Hurricane Ian (AL092022), 12 March 2026 revised version (original 2 April 2023), https://www.nhc.noaa.gov/data/tcr/AL092022_Ian.pdf — Florida: all 66 direct US deaths occurred in Florida (41 storm surge, 36 of them in Lee County; 12 freshwater flooding; 8 marine; 4 wind; 1 rough surf) (PDF p.12); 84 of the 90 indirect US deaths in Florida (p.13). economic_damage_overall_usd = $109.5 billion Florida share of the $112.9 billion US total (NOAA NCEI estimate, p.13). 11 migrants still missing are not counted (p.12). Separate infrastructure-only figure not reported (crop/agriculture losses given only as a range, $1.1–1.8 billion, p.13).
A14: 8 | B14: 39 | C14: 0 | D14: 0 | G14: NHC Tropical Cyclone Report: Hurricane Ian (AL092022), 12 March 2026 revised version (original 2 April 2023), https://www.nhc.noaa.gov/data/tcr/AL092022_Ian.pdf — South Carolina: no deaths listed for SC — all direct deaths were in Florida (p.12) and the indirect deaths were FL 84, NC 5, VA 1 (p.13), so recorded as 0 / 0. Storm surge flooded downtown Georgetown (p.14). No state-level USD figure; the remaining $3.4 billion of the US total is not split by state.
A15: 9 | B15: 50 | C15: 0 | D15: 5 | G15: NHC Tropical Cyclone Report: Hurricane Ian (AL092022), 12 March 2026 revised version (original 2 April 2023), https://www.nhc.noaa.gov/data/tcr/AL092022_Ian.pdf — North Carolina: 5 indirect deaths (PDF p.13, Fig. 16); no direct deaths outside Florida (p.12). ~579,000 customers lost power (p.14). No USD figure.
A16: 10 | B16: 51 | C16: 0 | D16: 1 | G16: NHC Tropical Cyclone Report: Hurricane Ian (AL092022), 12 March 2026 revised version (original 2 April 2023), https://www.nhc.noaa.gov/data/tcr/AL092022_Ian.pdf — Virginia: 1 indirect death (PDF p.13, Fig. 16); no direct deaths outside Florida (p.12). ~211,000 customers lost power (p.14). No USD figure.
A17: 11 | B17: 4 | E17: =INDEX(jamaica_parish_damage_ref!$D$6:$D$19,MATCH("Westmoreland",jamaica_parish_damage_ref!$A$6:$A$19,0))*1000000 -> 434000000 | F17: =INDEX(jamaica_parish_damage_ref!$F$6:$F$19,MATCH("Westmoreland",jamaica_parish_damage_ref!$A$6:$A$19,0))*1000000 -> 1409100000 | G17: Parish-level damage for Westmoreland parish, where this station is located (parish assignment by station location; Table 3 PDF p.24–27 of NHC report). Source: World Bank / GFDRR, Global Rapid Post-Disaster Damage Estimation (GRADE): Hurricane Melissa 2025 Jamaica, Table ES.1, PDF p.12 (printed p.2), https://www.gfdrr.org/sites/default/files/publication/GRADE%20Jamaica_FIN.pdf (landing page https://www.gfdrr.org/en/JamaicaGRADE). infrastructure_damage_usd = parish infrastructure damage; economic_damage_overall_usd = parish total direct physical damage (replacement cost; GRADE excludes economic losses such as lost sales/tourism). GRADE gives no site-level figures (low confidence at asset level, PDF p.11). The same parish figure is repeated for every station row in this parish — do NOT sum across rows. Preliminary Nov 2025 estimate. DEATHS: Government of Jamaica reports 15 confirmed death(s) for Westmoreland parish (of 45 island-wide; St Elizabeth 18, Westmoreland 15, St James 6, Hanover 2, Trelawny 2, St Ann 1, Portland 1) — total only; no official direct/indirect classification exists (NHC report p.13: 'unclear how many... direct'), so deaths_direct and deaths_indirect are left blank. Sources: Jamaica Information Service, https://jis.gov.jm/45-confirmed-deaths-from-hurricane-melissa/ ; UN OCHA Situation Report No. 4 (11 Nov 2025), https://www.unocha.org/publications/report/jamaica/jamaica-hurricane-melissa-situation-report-no-4-11-november . Repeated per station in the parish — do not sum.
A18: 12 | B18: 5 | E18: =INDEX(jamaica_parish_damage_ref!$D$6:$D$19,MATCH("Trelawny",jamaica_parish_damage_ref!$A$6:$A$19,0))*1000000 -> 296500000 | F18: =INDEX(jamaica_parish_damage_ref!$F$6:$F$19,MATCH("Trelawny",jamaica_parish_damage_ref!$A$6:$A$19,0))*1000000 -> 746800000 | G18: Parish-level damage for Trelawny parish, where this station is located (parish assignment by station location; Table 3 PDF p.24–27 of NHC report). Source: World Bank / GFDRR, Global Rapid Post-Disaster Damage Estimation (GRADE): Hurricane Melissa 2025 Jamaica, Table ES.1, PDF p.12 (printed p.2), https://www.gfdrr.org/sites/default/files/publication/GRADE%20Jamaica_FIN.pdf (landing page https://www.gfdrr.org/en/JamaicaGRADE). infrastructure_damage_usd = parish infrastructure damage; economic_damage_overall_usd = parish total direct physical damage (replacement cost; GRADE excludes economic losses such as lost sales/tourism). GRADE gives no site-level figures (low confidence at asset level, PDF p.11). The same parish figure is repeated for every station row in this parish — do NOT sum across rows. Preliminary Nov 2025 estimate. DEATHS: Government of Jamaica reports 2 confirmed death(s) for Trelawny parish (of 45 island-wide; St Elizabeth 18, Westmoreland 15, St James 6, Hanover 2, Trelawny 2, St Ann 1, Portland 1) — total only; no official direct/indirect classification exists (NHC report p.13: 'unclear how many... direct'), so deaths_direct and deaths_indirect are left blank. Sources: Jamaica Information Service, https://jis.gov.jm/45-confirmed-deaths-from-hurricane-melissa/ ; UN OCHA Situation Report No. 4 (11 Nov 2025), https://www.unocha.org/publications/report/jamaica/jamaica-hurricane-melissa-situation-report-no-4-11-november . Repeated per station in the parish — do not sum.
A19: 13 | B19: 6 | E19: =INDEX(jamaica_parish_damage_ref!$D$6:$D$19,MATCH("Saint Ann",jamaica_parish_damage_ref!$A$6:$A$19,0))*1000000 -> 154800000 | F19: =INDEX(jamaica_parish_damage_ref!$F$6:$F$19,MATCH("Saint Ann",jamaica_parish_damage_ref!$A$6:$A$19,0))*1000000 -> 552100000 | G19: Parish-level damage for Saint Ann parish, where this station is located (parish assignment by station location; Table 3 PDF p.24–27 of NHC report). Source: World Bank / GFDRR, Global Rapid Post-Disaster Damage Estimation (GRADE): Hurricane Melissa 2025 Jamaica, Table ES.1, PDF p.12 (printed p.2), https://www.gfdrr.org/sites/default/files/publication/GRADE%20Jamaica_FIN.pdf (landing page https://www.gfdrr.org/en/JamaicaGRADE). infrastructure_damage_usd = parish infrastructure damage; economic_damage_overall_usd = parish total direct physical damage (replacement cost; GRADE excludes economic losses such as lost sales/tourism). GRADE gives no site-level figures (low confidence at asset level, PDF p.11). The same parish figure is repeated for every station row in this parish — do NOT sum across rows. Preliminary Nov 2025 estimate. DEATHS: Government of Jamaica reports 1 confirmed death(s) for Saint Ann parish (of 45 island-wide; St Elizabeth 18, Westmoreland 15, St James 6, Hanover 2, Trelawny 2, St Ann 1, Portland 1) — total only; no official direct/indirect classification exists (NHC report p.13: 'unclear how many... direct'), so deaths_direct and deaths_indirect are left blank. Sources: Jamaica Information Service, https://jis.gov.jm/45-confirmed-deaths-from-hurricane-melissa/ ; UN OCHA Situation Report No. 4 (11 Nov 2025), https://www.unocha.org/publications/report/jamaica/jamaica-hurricane-melissa-situation-report-no-4-11-november . Repeated per station in the parish — do not sum.
A20: 14 | B20: 7 | E20: =INDEX(jamaica_parish_damage_ref!$D$6:$D$19,MATCH("Saint Elizabeth",jamaica_parish_damage_ref!$A$6:$A$19,0))*1000000 -> 763600000 | F20: =INDEX(jamaica_parish_damage_ref!$F$6:$F$19,MATCH("Saint Elizabeth",jamaica_parish_damage_ref!$A$6:$A$19,0))*1000000 -> 2286000000 | G20: Parish-level damage for Saint Elizabeth parish, where this station is located (parish assignment by station location; Table 3 PDF p.24–27 of NHC report). Source: World Bank / GFDRR, Global Rapid Post-Disaster Damage Estimation (GRADE): Hurricane Melissa 2025 Jamaica, Table ES.1, PDF p.12 (printed p.2), https://www.gfdrr.org/sites/default/files/publication/GRADE%20Jamaica_FIN.pdf (landing page https://www.gfdrr.org/en/JamaicaGRADE). infrastructure_damage_usd = parish infrastructure damage; economic_damage_overall_usd = parish total direct physical damage (replacement cost; GRADE excludes economic losses such as lost sales/tourism). GRADE gives no site-level figures (low confidence at asset level, PDF p.11). The same parish figure is repeated for every station row in this parish — do NOT sum across rows. Preliminary Nov 2025 estimate. DEATHS: Government of Jamaica reports 18 confirmed death(s) for Saint Elizabeth parish (of 45 island-wide; St Elizabeth 18, Westmoreland 15, St James 6, Hanover 2, Trelawny 2, St Ann 1, Portland 1) — total only; no official direct/indirect classification exists (NHC report p.13: 'unclear how many... direct'), so deaths_direct and deaths_indirect are left blank. Sources: Jamaica Information Service, https://jis.gov.jm/45-confirmed-deaths-from-hurricane-melissa/ ; UN OCHA Situation Report No. 4 (11 Nov 2025), https://www.unocha.org/publications/report/jamaica/jamaica-hurricane-melissa-situation-report-no-4-11-november . Repeated per station in the parish — do not sum.
A21: 15 | B21: 8 | E21: =INDEX(jamaica_parish_damage_ref!$D$6:$D$19,MATCH("Westmoreland",jamaica_parish_damage_ref!$A$6:$A$19,0))*1000000 -> 434000000 | F21: =INDEX(jamaica_parish_damage_ref!$F$6:$F$19,MATCH("Westmoreland",jamaica_parish_damage_ref!$A$6:$A$19,0))*1000000 -> 1409100000 | G21: Parish-level damage for Westmoreland parish, where this station is located (parish assignment by station location; Table 3 PDF p.24–27 of NHC report). Source: World Bank / GFDRR, Global Rapid Post-Disaster Damage Estimation (GRADE): Hurricane Melissa 2025 Jamaica, Table ES.1, PDF p.12 (printed p.2), https://www.gfdrr.org/sites/default/files/publication/GRADE%20Jamaica_FIN.pdf (landing page https://www.gfdrr.org/en/JamaicaGRADE). infrastructure_damage_usd = parish infrastructure damage; economic_damage_overall_usd = parish total direct physical damage (replacement cost; GRADE excludes economic losses such as lost sales/tourism). GRADE gives no site-level figures (low confidence at asset level, PDF p.11). The same parish figure is repeated for every station row in this parish — do NOT sum across rows. Preliminary Nov 2025 estimate. DEATHS: Government of Jamaica reports 15 confirmed death(s) for Westmoreland parish (of 45 island-wide; St Elizabeth 18, Westmoreland 15, St James 6, Hanover 2, Trelawny 2, St Ann 1, Portland 1) — total only; no official direct/indirect classification exists (NHC report p.13: 'unclear how many... direct'), so deaths_direct and deaths_indirect are left blank. Sources: Jamaica Information Service, https://jis.gov.jm/45-confirmed-deaths-from-hurricane-melissa/ ; UN OCHA Situation Report No. 4 (11 Nov 2025), https://www.unocha.org/publications/report/jamaica/jamaica-hurricane-melissa-situation-report-no-4-11-november . Repeated per station in the parish — do not sum.
A22: 16 | B22: 9 | E22: =INDEX(jamaica_parish_damage_ref!$D$6:$D$19,MATCH("Westmoreland",jamaica_parish_damage_ref!$A$6:$A$19,0))*1000000 -> 434000000 | F22: =INDEX(jamaica_parish_damage_ref!$F$6:$F$19,MATCH("Westmoreland",jamaica_parish_damage_ref!$A$6:$A$19,0))*1000000 -> 1409100000 | G22: Parish-level damage for Westmoreland parish, where this station is located (parish assignment by station location; Table 3 PDF p.24–27 of NHC report). Source: World Bank / GFDRR, Global Rapid Post-Disaster Damage Estimation (GRADE): Hurricane Melissa 2025 Jamaica, Table ES.1, PDF p.12 (printed p.2), https://www.gfdrr.org/sites/default/files/publication/GRADE%20Jamaica_FIN.pdf (landing page https://www.gfdrr.org/en/JamaicaGRADE). infrastructure_damage_usd = parish infrastructure damage; economic_damage_overall_usd = parish total direct physical damage (replacement cost; GRADE excludes economic losses such as lost sales/tourism). GRADE gives no site-level figures (low confidence at asset level, PDF p.11). The same parish figure is repeated for every station row in this parish — do NOT sum across rows. Preliminary Nov 2025 estimate. DEATHS: Government of Jamaica reports 15 confirmed death(s) for Westmoreland parish (of 45 island-wide; St Elizabeth 18, Westmoreland 15, St James 6, Hanover 2, Trelawny 2, St Ann 1, Portland 1) — total only; no official direct/indirect classification exists (NHC report p.13: 'unclear how many... direct'), so deaths_direct and deaths_indirect are left blank. Sources: Jamaica Information Service, https://jis.gov.jm/45-confirmed-deaths-from-hurricane-melissa/ ; UN OCHA Situation Report No. 4 (11 Nov 2025), https://www.unocha.org/publications/report/jamaica/jamaica-hurricane-melissa-situation-report-no-4-11-november . Repeated per station in the parish — do not sum.
A23: 17 | B23: 10 | E23: =INDEX(jamaica_parish_damage_ref!$D$6:$D$19,MATCH("Trelawny",jamaica_parish_damage_ref!$A$6:$A$19,0))*1000000 -> 296500000 | F23: =INDEX(jamaica_parish_damage_ref!$F$6:$F$19,MATCH("Trelawny",jamaica_parish_damage_ref!$A$6:$A$19,0))*1000000 -> 746800000 | G23: Parish-level damage for Trelawny parish, where this station is located (parish assignment by station location; Table 3 PDF p.24–27 of NHC report). Source: World Bank / GFDRR, Global Rapid Post-Disaster Damage Estimation (GRADE): Hurricane Melissa 2025 Jamaica, Table ES.1, PDF p.12 (printed p.2), https://www.gfdrr.org/sites/default/files/publication/GRADE%20Jamaica_FIN.pdf (landing page https://www.gfdrr.org/en/JamaicaGRADE). infrastructure_damage_usd = parish infrastructure damage; economic_damage_overall_usd = parish total direct physical damage (replacement cost; GRADE excludes economic losses such as lost sales/tourism). GRADE gives no site-level figures (low confidence at asset level, PDF p.11). The same parish figure is repeated for every station row in this parish — do NOT sum across rows. Preliminary Nov 2025 estimate. DEATHS: Government of Jamaica reports 2 confirmed death(s) for Trelawny parish (of 45 island-wide; St Elizabeth 18, Westmoreland 15, St James 6, Hanover 2, Trelawny 2, St Ann 1, Portland 1) — total only; no official direct/indirect classification exists (NHC report p.13: 'unclear how many... direct'), so deaths_direct and deaths_indirect are left blank. Sources: Jamaica Information Service, https://jis.gov.jm/45-confirmed-deaths-from-hurricane-melissa/ ; UN OCHA Situation Report No. 4 (11 Nov 2025), https://www.unocha.org/publications/report/jamaica/jamaica-hurricane-melissa-situation-report-no-4-11-november . Repeated per station in the parish — do not sum.
A24: 18 | B24: 11 | E24: =INDEX(jamaica_parish_damage_ref!$D$6:$D$19,MATCH("Saint Ann",jamaica_parish_damage_ref!$A$6:$A$19,0))*1000000 -> 154800000 | F24: =INDEX(jamaica_parish_damage_ref!$F$6:$F$19,MATCH("Saint Ann",jamaica_parish_damage_ref!$A$6:$A$19,0))*1000000 -> 552100000 | G24: Parish-level damage for Saint Ann parish, where this station is located (parish assignment by station location; Table 3 PDF p.24–27 of NHC report). Source: World Bank / GFDRR, Global Rapid Post-Disaster Damage Estimation (GRADE): Hurricane Melissa 2025 Jamaica, Table ES.1, PDF p.12 (printed p.2), https://www.gfdrr.org/sites/default/files/publication/GRADE%20Jamaica_FIN.pdf (landing page https://www.gfdrr.org/en/JamaicaGRADE). infrastructure_damage_usd = parish infrastructure damage; economic_damage_overall_usd = parish total direct physical damage (replacement cost; GRADE excludes economic losses such as lost sales/tourism). GRADE gives no site-level figures (low confidence at asset level, PDF p.11). The same parish figure is repeated for every station row in this parish — do NOT sum across rows. Preliminary Nov 2025 estimate. DEATHS: Government of Jamaica reports 1 confirmed death(s) for Saint Ann parish (of 45 island-wide; St Elizabeth 18, Westmoreland 15, St James 6, Hanover 2, Trelawny 2, St Ann 1, Portland 1) — total only; no official direct/indirect classification exists (NHC report p.13: 'unclear how many... direct'), so deaths_direct and deaths_indirect are left blank. Sources: Jamaica Information Service, https://jis.gov.jm/45-confirmed-deaths-from-hurricane-melissa/ ; UN OCHA Situation Report No. 4 (11 Nov 2025), https://www.unocha.org/publications/report/jamaica/jamaica-hurricane-melissa-situation-report-no-4-11-november . Repeated per station in the parish — do not sum.
A25: 19 | B25: 12 | E25: =INDEX(jamaica_parish_damage_ref!$D$6:$D$19,MATCH("Clarendon",jamaica_parish_damage_ref!$A$6:$A$19,0))*1000000 -> 112000000 | F25: =INDEX(jamaica_parish_damage_ref!$F$6:$F$19,MATCH("Clarendon",jamaica_parish_damage_ref!$A$6:$A$19,0))*1000000 -> 318600000 | G25: Parish-level damage for Clarendon parish, where this station is located (parish assignment by station location; Table 3 PDF p.24–27 of NHC report). Source: World Bank / GFDRR, Global Rapid Post-Disaster Damage Estimation (GRADE): Hurricane Melissa 2025 Jamaica, Table ES.1, PDF p.12 (printed p.2), https://www.gfdrr.org/sites/default/files/publication/GRADE%20Jamaica_FIN.pdf (landing page https://www.gfdrr.org/en/JamaicaGRADE). infrastructure_damage_usd = parish infrastructure damage; economic_damage_overall_usd = parish total direct physical damage (replacement cost; GRADE excludes economic losses such as lost sales/tourism). GRADE gives no site-level figures (low confidence at asset level, PDF p.11). The same parish figure is repeated for every station row in this parish — do NOT sum across rows. Preliminary Nov 2025 estimate. DEATHS: Government of Jamaica reports no deaths listed for Clarendon parish (of 45 island-wide; St Elizabeth 18, Westmoreland 15, St James 6, Hanover 2, Trelawny 2, St Ann 1, Portland 1) — total only; no official direct/indirect classification exists (NHC report p.13: 'unclear how many... direct'), so deaths_direct and deaths_indirect are left blank. Sources: Jamaica Information Service, https://jis.gov.jm/45-confirmed-deaths-from-hurricane-melissa/ ; UN OCHA Situation Report No. 4 (11 Nov 2025), https://www.unocha.org/publications/report/jamaica/jamaica-hurricane-melissa-situation-report-no-4-11-november . Repeated per station in the parish — do not sum.
A26: 20 | B26: 13 | E26: =INDEX(jamaica_parish_damage_ref!$D$6:$D$19,MATCH("Saint Andrew",jamaica_parish_damage_ref!$A$6:$A$19,0))*1000000 -> 30600000 | F26: =INDEX(jamaica_parish_damage_ref!$F$6:$F$19,MATCH("Saint Andrew",jamaica_parish_damage_ref!$A$6:$A$19,0))*1000000 -> 139500000 | G26: Parish-level damage for Saint Andrew parish, where this station is located (parish assignment by station location; Table 3 PDF p.24–27 of NHC report). Source: World Bank / GFDRR, Global Rapid Post-Disaster Damage Estimation (GRADE): Hurricane Melissa 2025 Jamaica, Table ES.1, PDF p.12 (printed p.2), https://www.gfdrr.org/sites/default/files/publication/GRADE%20Jamaica_FIN.pdf (landing page https://www.gfdrr.org/en/JamaicaGRADE). infrastructure_damage_usd = parish infrastructure damage; economic_damage_overall_usd = parish total direct physical damage (replacement cost; GRADE excludes economic losses such as lost sales/tourism). GRADE gives no site-level figures (low confidence at asset level, PDF p.11). The same parish figure is repeated for every station row in this parish — do NOT sum across rows. Preliminary Nov 2025 estimate. DEATHS: Government of Jamaica reports no deaths listed for Saint Andrew parish (of 45 island-wide; St Elizabeth 18, Westmoreland 15, St James 6, Hanover 2, Trelawny 2, St Ann 1, Portland 1) — total only; no official direct/indirect classification exists (NHC report p.13: 'unclear how many... direct'), so deaths_direct and deaths_indirect are left blank. Sources: Jamaica Information Service, https://jis.gov.jm/45-confirmed-deaths-from-hurricane-melissa/ ; UN OCHA Situation Report No. 4 (11 Nov 2025), https://www.unocha.org/publications/report/jamaica/jamaica-hurricane-melissa-situation-report-no-4-11-november . Repeated per station in the parish — do not sum.
A27: 21 | B27: 14 | E27: =INDEX(jamaica_parish_damage_ref!$D$6:$D$19,MATCH("Saint Andrew",jamaica_parish_damage_ref!$A$6:$A$19,0))*1000000 -> 30600000 | F27: =INDEX(jamaica_parish_damage_ref!$F$6:$F$19,MATCH("Saint Andrew",jamaica_parish_damage_ref!$A$6:$A$19,0))*1000000 -> 139500000 | G27: Parish-level damage for Saint Andrew parish, where this station is located (parish assignment by station location; Table 3 PDF p.24–27 of NHC report). Source: World Bank / GFDRR, Global Rapid Post-Disaster Damage Estimation (GRADE): Hurricane Melissa 2025 Jamaica, Table ES.1, PDF p.12 (printed p.2), https://www.gfdrr.org/sites/default/files/publication/GRADE%20Jamaica_FIN.pdf (landing page https://www.gfdrr.org/en/JamaicaGRADE). infrastructure_damage_usd = parish infrastructure damage; economic_damage_overall_usd = parish total direct physical damage (replacement cost; GRADE excludes economic losses such as lost sales/tourism). GRADE gives no site-level figures (low confidence at asset level, PDF p.11). The same parish figure is repeated for every station row in this parish — do NOT sum across rows. Preliminary Nov 2025 estimate. DEATHS: Government of Jamaica reports no deaths listed for Saint Andrew parish (of 45 island-wide; St Elizabeth 18, Westmoreland 15, St James 6, Hanover 2, Trelawny 2, St Ann 1, Portland 1) — total only; no official direct/indirect classification exists (NHC report p.13: 'unclear how many... direct'), so deaths_direct and deaths_indirect are left blank. Sources: Jamaica Information Service, https://jis.gov.jm/45-confirmed-deaths-from-hurricane-melissa/ ; UN OCHA Situation Report No. 4 (11 Nov 2025), https://www.unocha.org/publications/report/jamaica/jamaica-hurricane-melissa-situation-report-no-4-11-november . Repeated per station in the parish — do not sum.
A28: 22 | B28: 15 | E28: =INDEX(jamaica_parish_damage_ref!$D$6:$D$19,MATCH("Saint James",jamaica_parish_damage_ref!$A$6:$A$19,0))*1000000 -> 587000000 | F28: =INDEX(jamaica_parish_damage_ref!$F$6:$F$19,MATCH("Saint James",jamaica_parish_damage_ref!$A$6:$A$19,0))*1000000 -> 1822100000 | G28: Parish-level damage for Saint James parish, where this station is located (parish assignment by station location; Table 3 PDF p.24–27 of NHC report). Source: World Bank / GFDRR, Global Rapid Post-Disaster Damage Estimation (GRADE): Hurricane Melissa 2025 Jamaica, Table ES.1, PDF p.12 (printed p.2), https://www.gfdrr.org/sites/default/files/publication/GRADE%20Jamaica_FIN.pdf (landing page https://www.gfdrr.org/en/JamaicaGRADE). infrastructure_damage_usd = parish infrastructure damage; economic_damage_overall_usd = parish total direct physical damage (replacement cost; GRADE excludes economic losses such as lost sales/tourism). GRADE gives no site-level figures (low confidence at asset level, PDF p.11). The same parish figure is repeated for every station row in this parish — do NOT sum across rows. Preliminary Nov 2025 estimate. DEATHS: Government of Jamaica reports 6 confirmed death(s) for Saint James parish (of 45 island-wide; St Elizabeth 18, Westmoreland 15, St James 6, Hanover 2, Trelawny 2, St Ann 1, Portland 1) — total only; no official direct/indirect classification exists (NHC report p.13: 'unclear how many... direct'), so deaths_direct and deaths_indirect are left blank. Sources: Jamaica Information Service, https://jis.gov.jm/45-confirmed-deaths-from-hurricane-melissa/ ; UN OCHA Situation Report No. 4 (11 Nov 2025), https://www.unocha.org/publications/report/jamaica/jamaica-hurricane-melissa-situation-report-no-4-11-november . Repeated per station in the parish — do not sum.
A29: 23 | B29: 16 | E29: =INDEX(jamaica_parish_damage_ref!$D$6:$D$19,MATCH("Kingston",jamaica_parish_damage_ref!$A$6:$A$19,0))*1000000 -> 7000000 | F29: =INDEX(jamaica_parish_damage_ref!$F$6:$F$19,MATCH("Kingston",jamaica_parish_damage_ref!$A$6:$A$19,0))*1000000 -> 14000000 | G29: Parish-level damage for Kingston parish, where this station is located (parish assignment by station location; Table 3 PDF p.24–27 of NHC report). Source: World Bank / GFDRR, Global Rapid Post-Disaster Damage Estimation (GRADE): Hurricane Melissa 2025 Jamaica, Table ES.1, PDF p.12 (printed p.2), https://www.gfdrr.org/sites/default/files/publication/GRADE%20Jamaica_FIN.pdf (landing page https://www.gfdrr.org/en/JamaicaGRADE). infrastructure_damage_usd = parish infrastructure damage; economic_damage_overall_usd = parish total direct physical damage (replacement cost; GRADE excludes economic losses such as lost sales/tourism). GRADE gives no site-level figures (low confidence at asset level, PDF p.11). The same parish figure is repeated for every station row in this parish — do NOT sum across rows. Preliminary Nov 2025 estimate. DEATHS: Government of Jamaica reports no deaths listed for Kingston parish (of 45 island-wide; St Elizabeth 18, Westmoreland 15, St James 6, Hanover 2, Trelawny 2, St Ann 1, Portland 1) — total only; no official direct/indirect classification exists (NHC report p.13: 'unclear how many... direct'), so deaths_direct and deaths_indirect are left blank. Sources: Jamaica Information Service, https://jis.gov.jm/45-confirmed-deaths-from-hurricane-melissa/ ; UN OCHA Situation Report No. 4 (11 Nov 2025), https://www.unocha.org/publications/report/jamaica/jamaica-hurricane-melissa-situation-report-no-4-11-november . Repeated per station in the parish — do not sum.
A30: 24 | B30: 93 | C30: 1 | D30: 0 | G30: NHC Fiona TCR — Guadeloupe: 1 direct death; report describes substantial damage to homes, roads, bridges and infrastructure but gives no separate USD damage total for Guadeloupe. PDF pp.8–9.
A31: 25 | B31: 94 | C31: 2 | D31: 21 | F31: $2.500.000.000 | G31: NHC Fiona TCR — Puerto Rico: 2 direct and 21 indirect deaths. NCEI estimate quoted by NHC = US$2.5 billion in damage. Agricultural losses over US$150 million are reported separately and are not treated as
G32: infrastructure_damage_usd
G33: . PDF pp.8–9.
A34: 26 | B34: 95 | C34: 2 | D34: 0 | G34: NHC Fiona TCR — Dominican Republic: 2 direct deaths; more than 8,500 homes damaged and over 2,000 destroyed, but the report gives no USD damage estimate. PDF pp.8–9.
A35: 27 | B35: 96 | C35: 0 | D35: 0 | G35: NHC Fiona TCR — Turks and Caicos: no deaths in the report's casualty totals; significant damage described on Grand Turk and other islands, but no USD estimate. PDF p.9.
A36: 28 | B36: 114 | C36: 0 | D36: 0 | G36: NHC Fiona TCR — Bermuda: no Fiona deaths in the report's complete casualty totals; minor structural/power impacts described, but no USD estimate. PDF pp.8–9.
A37: 29 | B37: 123 | C37: 2 | D37: 1 | G37: NHC Fiona TCR — Canada: 2 direct deaths and 1 indirect death. About CAD$800 million in insured losses is reported, but this is neither USD nor total economic damage, so economic_damage_overall_usd is left blank. PDF pp.8–10.

Sheet location_entity
A1: Location Entity
A2: Stores the geographic reference used by meteorological observations.
A3: Primary key: location_id • Referenced by meteorological_data through location_id
A5: location_id | B5: region | C5: country | D5: latitude | E5: longitude | F5: source
A6: 0 | B6: Westmoreland Parish, western Jamaica (landfall near New Hope) | C6: Jamaica | D6: 18.1 | E6: -78 | F6: NHC Tropical Cyclone Report: Hurricane Melissa (AL132025), 19 May 2026 revised version, https://www.nhc.noaa.gov/data/tcr/AL132025_Melissa.pdf — landfall position (Table 1, PDF p.22; text p.4, p.6). Longitude negative = °W. Region/parish: p.6.
A7: 1 | B7: Santiago de Cuba Province, eastern Cuba (landfall near Chivirico) | C7: Cuba | D7: 20 | E7: -76.2 | F7: NHC Tropical Cyclone Report: Hurricane Melissa (AL132025), 19 May 2026 revised version, https://www.nhc.noaa.gov/data/tcr/AL132025_Melissa.pdf — landfall position (Table 1, PDF p.22; text p.4, p.7). Longitude negative = °W.
A8: 2 | B8: Long Island, southeastern Bahamas (first landfall near Buckley's Settlement) | C8: Bahamas | D8: 23.1 | E8: -75 | F8: NHC Tropical Cyclone Report: Hurricane Melissa (AL132025), 19 May 2026 revised version, https://www.nhc.noaa.gov/data/tcr/AL132025_Melissa.pdf — landfall position (Table 1, PDF p.22; text p.4, p.8). Longitude negative = °W.
A9: 3 | B9: Southern peninsula (Sud Department), Haiti | C9: Haiti | F9: NHC Tropical Cyclone Report: Hurricane Melissa (AL132025), 19 May 2026 revised version, https://www.nhc.noaa.gov/data/tcr/AL132025_Melissa.pdf — region from rainfall section, PDF p.10. Report gives no coordinates for Haiti (no landfall), so latitude/longitude left blank.
A10: 4 | B10: New Hope Primary School, Westmoreland Parish | C10: Jamaica | D10: 18.09 | E10: -77.97 | F10: NHC Tropical Cyclone Report: Hurricane Melissa (AL132025), 19 May 2026 revised version, https://www.nhc.noaa.gov/data/tcr/AL132025_Melissa.pdf — Table 3, PDF p.27 (station, coordinates, sustained 47 kt, gust 114 kt at 1600 UTC 28 Oct, min pressure 913.5 mb). Longitude negative = °W.
A11: 5 | B11: Hampden, Trelawny Parish | C11: Jamaica | D11: 18.44 | E11: -77.75 | F11: NHC Tropical Cyclone Report: Hurricane Melissa (AL132025), 19 May 2026 revised version, https://www.nhc.noaa.gov/data/tcr/AL132025_Melissa.pdf — Table 3, PDF p.27 (sustained 57 kt, gust 105 kt, min pressure 958 mb). Longitude negative = °W.
A12: 6 | B12: Bamboo, St. Ann Parish | C12: Jamaica | D12: 18.4 | E12: -77.28 | F12: NHC Tropical Cyclone Report: Hurricane Melissa (AL132025), 19 May 2026 revised version, https://www.nhc.noaa.gov/data/tcr/AL132025_Melissa.pdf — Table 3, PDF p.26 (sustained 45 kt, gust 90 kt, min pressure 972.5 mb). Longitude negative = °W.
A13: 7 | B13: Appleton Estate, St. Elizabeth Parish | C13: Jamaica | D13: 18.17 | E13: -77.72 | F13: NHC Tropical Cyclone Report: Hurricane Melissa (AL132025), 19 May 2026 revised version, https://www.nhc.noaa.gov/data/tcr/AL132025_Melissa.pdf — Table 3, PDF p.26 (sustained 40 kt, gust 96 kt, min pressure 964.6 mb). Longitude negative = °W.
A14: 8 | B14: Mountainside Primary School, Westmoreland Parish | C14: Jamaica | D14: 17.98 | E14: -77.75 | F14: NHC Tropical Cyclone Report: Hurricane Melissa (AL132025), 19 May 2026 revised version, https://www.nhc.noaa.gov/data/tcr/AL132025_Melissa.pdf — Table 3, PDF p.27 (sustained 56 kt, gust 90 kt, min pressure 974.8 mb, rain 20.01 in). Longitude negative = °W.
A15: 9 | B15: Newcombe Valley Primary School, Westmoreland Parish | C15: Jamaica | D15: 17.92 | E15: -77.76 | F15: NHC Tropical Cyclone Report: Hurricane Melissa (AL132025), 19 May 2026 revised version, https://www.nhc.noaa.gov/data/tcr/AL132025_Melissa.pdf — Table 3, PDF p.27 (sustained 54 kt, gust 93 kt, min pressure 972.5 mb). Longitude negative = °W.
A16: 10 | B16: Orange Valley, Trelawny Parish | C16: Jamaica | D16: 18.47 | E16: -77.73 | F16: NHC Tropical Cyclone Report: Hurricane Melissa (AL132025), 19 May 2026 revised version, https://www.nhc.noaa.gov/data/tcr/AL132025_Melissa.pdf — Table 3, PDF p.27 (sustained 44 kt, gust 88 kt, min pressure 960.2 mb, rain 9.29 in). Longitude negative = °W.
A17: 11 | B17: Minards, St. Ann Parish | C17: Jamaica | D17: 18.41 | E17: -77.38 | F17: NHC Tropical Cyclone Report: Hurricane Melissa (AL132025), 19 May 2026 revised version, https://www.nhc.noaa.gov/data/tcr/AL132025_Melissa.pdf — Table 3, PDF p.26 (sustained 44 kt, gust 85 kt, min pressure 965.9 mb, rain 10.66 in). Longitude negative = °W.
A18: 12 | B18: Mason River, Clarendon Parish | C18: Jamaica | D18: 18.2 | E18: -77.26 | F18: NHC Tropical Cyclone Report: Hurricane Melissa (AL132025), 19 May 2026 revised version, https://www.nhc.noaa.gov/data/tcr/AL132025_Melissa.pdf — Table 3, PDF p.24 (sustained 25 kt, gust 68 kt, min pressure 984.1 mb, rain 13.16 in). Longitude negative = °W.
A19: 13 | B19: Woodford, Kingston & St. Andrew Parish | C19: Jamaica | D19: 18.07 | E19: -76.75 | F19: NHC Tropical Cyclone Report: Hurricane Melissa (AL132025), 19 May 2026 revised version, https://www.nhc.noaa.gov/data/tcr/AL132025_Melissa.pdf — Table 3, PDF p.25 (sustained 37 kt, gust 69 kt, min pressure 993.7 mb, rain 7.35 in). Longitude negative = °W.
A20: 14 | B20: Mavis Bank, Kingston & St. Andrew Parish | C20: Jamaica | D20: 18.03 | E20: -76.65 | F20: NHC Tropical Cyclone Report: Hurricane Melissa (AL132025), 19 May 2026 revised version, https://www.nhc.noaa.gov/data/tcr/AL132025_Melissa.pdf — Table 3, PDF p.25 (sustained 10 kt, gust 37 kt, min pressure 993.6 mb, rain 22.32 in). Longitude negative = °W.
